<?xml version="1.0" encoding="utf-8"?>
<!-- This URDF was automatically created by SolidWorks to URDF Exporter! Originally created by Stephen Brawner (brawner@gmail.com) 
     Commit Version: 1.5.1-0-g916b5db  Build Version: 1.5.7152.31018
     For more information, please see http://wiki.ros.org/sw_urdf_exporter -->
<robot
  name="gemini_description">
	
<!-- Used for fixing robot to Gazebo 'base_link' -->
  <link name="world"/>

  <joint name="fixed" type="fixed">
    <parent link="world"/>
    <child link="base_link"/>
  </joint>


  <link
    name="base_link">
    <inertial>
      <origin
        xyz="0.534196245581179 0.318340540936641 1.00075295664558"
        rpy="0 0 0" />
      <mass
        value="4.52933028478602" />
      <inertia
        ixx="0.972928286231666"
        ixy="-1.76112183995259E-18"
        ixz="-1.39343163695887E-18"
        iyy="0.0439598829889821"
        iyz="-1.26402728667595E-16"
        izz="0.965992471324959" />
    </inertial>
    <visual>
      <origin
        xyz="0 0 0"
        rpy="0 0 0" />
      <geometry>
        <mesh
          filename="package://gemini_description/meshes/base_link.STL" />
      </geometry>
      <material
        name="">
        <color
          rgba="1 1 1 1" />
      </material>
    </visual>
    <collision>
      <origin
        xyz="0 0 0"
        rpy="0 0 0" />
      <geometry>
        <mesh
          filename="package://gemini_description/meshes/base_link.STL" />
      </geometry>
    </collision>
  </link>
  <link
    name="r_shoulder_ball">
    <inertial>
      <origin
        xyz="6.2371143805251E-09 5.1601216632946E-09 0.0405440960537498"
        rpy="0 0 0" />
      <mass
        value="0.0544711802480257" />
      <inertia
        ixx="4.16386347275612E-05"
        ixy="-8.02979166423697E-11"
        ixz="-9.44432762026392E-12"
        iyy="4.62851153976195E-05"
        iyz="-3.59594411893369E-11"
        izz="3.82219033168237E-05" />
    </inertial>
    <visual>
      <origin
        xyz="0 0 0"
        rpy="0 0 0" />
      <geometry>
        <mesh
          filename="package://gemini_description/meshes/r_shoulder_ball.STL" />
      </geometry>
      <material
        name="">
        <color
          rgba="1 1 1 1" />
      </material>
    </visual>
    <collision>
      <origin
        xyz="0 0 0"
        rpy="0 0 0" />
      <geometry>
        <mesh
          filename="package://gemini_description/meshes/r_shoulder_ball.STL" />
      </geometry>
    </collision>
  </link>
  <joint
    name="rs1"
    type="continuous">
    <origin
      xyz="0.5342 -0.72092 1.1783"
      rpy="1.5708 0.0040924 0" />
    <parent
      link="base_link" />
    <child
      link="r_shoulder_ball" />
    <axis
      xyz="0 0 1" />
  </joint>
  <link
    name="r_bicept">
    <inertial>
      <origin
        xyz="-3.22171700650742E-07 2.47687296173194E-06 0.103443210779644"
        rpy="0 0 0" />
      <mass
        value="0.27245990707176" />
      <inertia
        ixx="0.000714949661933855"
        ixy="-1.1719557948945E-05"
        ixz="-2.95555807574608E-09"
        iyy="0.000573884895229664"
        iyz="-2.95084293669371E-08"
        izz="0.000255692784911415" />
    </inertial>
    <visual>
      <origin
        xyz="0 0 0"
        rpy="0 0 0" />
      <geometry>
        <mesh
          filename="package://gemini_description/meshes/r_bicept.STL" />
      </geometry>
      <material
        name="">
        <color
          rgba="1 1 1 1" />
      </material>
    </visual>
    <collision>
      <origin
        xyz="0 0 0"
        rpy="0 0 0" />
      <geometry>
        <mesh
          filename="package://gemini_description/meshes/r_bicept.STL" />
      </geometry>
    </collision>
  </link>
  <joint
    name="rs2"
    type="continuous">
    <origin
      xyz="0 0 0.029008"
      rpy="0 1.5481 -1.5708" />
    <parent
      link="r_shoulder_ball" />
    <child
      link="r_bicept" />
    <axis
      xyz="0 1 0" />
  </joint>
  <link
    name="r_elbow_ball">
    <inertial>
      <origin
        xyz="4.82088047260021E-09 6.76370104368829E-09 -0.0396882448554229"
        rpy="0 0 0" />
      <mass
        value="0.0544711765716635" />
      <inertia
        ixx="4.16386322117843E-05"
        ixy="-7.99853524786356E-11"
        ixz="-1.39495005403985E-11"
        iyy="4.62851096230032E-05"
        iyz="-3.77840023423479E-11"
        izz="3.82219023335048E-05" />
    </inertial>
    <visual>
      <origin
        xyz="0 0 0"
        rpy="0 0 0" />
      <geometry>
        <mesh
          filename="package://gemini_description/meshes/r_elbow_ball.STL" />
      </geometry>
      <material
        name="">
        <color
          rgba="1 1 1 1" />
      </material>
    </visual>
    <collision>
      <origin
        xyz="0 0 0"
        rpy="0 0 0" />
      <geometry>
        <mesh
          filename="package://gemini_description/meshes/r_elbow_ball.STL" />
      </geometry>
    </collision>
  </link>
  <joint
    name="re1"
    type="continuous">
    <origin
      xyz="0 0 0.24215"
      rpy="-3.1416 0 -0.00012242" />
    <parent
      link="r_bicept" />
    <child
      link="r_elbow_ball" />
    <axis
      xyz="0 0 1" />
  </joint>
  <link
    name="r_forearm">
    <inertial>
      <origin
        xyz="-0.0134758227402774 -0.133680447778059 -0.00117188051040784"
        rpy="0 0 0" />
      <mass
        value="0.399020633136462" />
      <inertia
        ixx="0.000800265445630862"
        ixy="-5.11977241866116E-05"
        ixz="8.94994643330829E-06"
        iyy="0.000304300255531216"
        iyz="-1.29246447280764E-05"
        izz="0.000582445526550102" />
    </inertial>
    <visual>
      <origin
        xyz="0 0 0"
        rpy="0 0 0" />
      <geometry>
        <mesh
          filename="package://gemini_description/meshes/r_forearm.STL" />
      </geometry>
      <material
        name="">
        <color
          rgba="0.792156862745098 0.819607843137255 0.933333333333333 1" />
      </material>
    </visual>
    <collision>
      <origin
        xyz="0 0 0"
        rpy="0 0 0" />
      <geometry>
        <mesh
          filename="package://gemini_description/meshes/r_forearm.STL" />
      </geometry>
    </collision>
  </link>
  <joint
    name="re2"
    type="continuous">
    <origin
      xyz="0 0 -0.05"
      rpy="1.5935 -0.0040913 -1.571" />
    <parent
      link="r_elbow_ball" />
    <child
      link="r_forearm" />
    <axis
      xyz="0.00021537 0.022713 0.99974" />
  </joint>
  <link
    name="r_wrist">
    <inertial>
      <origin
        xyz="0.0133544170175107 -6.99440505513849E-15 -1.18793863634892E-14"
        rpy="0 0 0" />
      <mass
        value="0.0120708298165578" />
      <inertia
        ixx="4.50218447918875E-06"
        ixy="7.90784665600694E-22"
        ixz="1.35988492703718E-21"
        iyy="4.73440053913696E-06"
        iyz="1.61995051162385E-20"
        izz="1.51423045487236E-06" />
    </inertial>
    <visual>
      <origin
        xyz="0 0 0"
        rpy="0 0 0" />
      <geometry>
        <mesh
          filename="package://gemini_description/meshes/r_wrist.STL" />
      </geometry>
      <material
        name="">
        <color
          rgba="1 1 1 1" />
      </material>
    </visual>
    <collision>
      <origin
        xyz="0 0 0"
        rpy="0 0 0" />
      <geometry>
        <mesh
          filename="package://gemini_description/meshes/r_wrist.STL" />
      </geometry>
    </collision>
  </link>
  <joint
    name="rw1"
    type="continuous">
    <origin
      xyz="-0.023654 -0.23732 0.0053241"
      rpy="0.2299 -0.022623 -1.6708" />
    <parent
      link="r_forearm" />
    <child
      link="r_wrist" />
    <axis
      xyz="1 0 0" />
  </joint>
  <link
    name="r_hand">
    <inertial>
      <origin
        xyz="0.0619058412967715 0.0045109063152311 0.000800345401573588"
        rpy="0 0 0" />
      <mass
        value="0.178955913251513" />
      <inertia
        ixx="0.000136528763256749"
        ixy="2.96325083363903E-05"
        ixz="2.81195853619585E-06"
        iyy="0.00026516103310724"
        iyz="5.30420772551096E-07"
        izz="0.000391206453836346" />
    </inertial>
    <visual>
      <origin
        xyz="0 0 0"
        rpy="0 0 0" />
      <geometry>
        <mesh
          filename="package://gemini_description/meshes/r_hand.STL" />
      </geometry>
      <material
        name="">
        <color
          rgba="0.792156862745098 0.819607843137255 0.933333333333333 1" />
      </material>
    </visual>
    <collision>
      <origin
        xyz="0 0 0"
        rpy="0 0 0" />
      <geometry>
        <mesh
          filename="package://gemini_description/meshes/r_hand.STL" />
      </geometry>
    </collision>
  </link>
  <joint
    name="rw2"
    type="continuous">
    <origin
      xyz="0.028848 0 0"
      rpy="1.5708 0 0.091473" />
    <parent
      link="r_wrist" />
    <child
      link="r_hand" />
    <axis
      xyz="0 1 0" />
  </joint>
  <link
    name="l_shoulder_ball">
    <inertial>
      <origin
        xyz="4.7354530297028E-09 4.96404783945081E-09 -0.0394697291071835"
        rpy="0 0 0" />
      <mass
        value="0.054471175913326" />
      <inertia
        ixx="4.16386318474759E-05"
        ixy="-8.00732427287903E-11"
        ixz="-1.20199059472294E-11"
        iyy="4.62851094387098E-05"
        iyz="-3.59209946397337E-11"
        izz="3.82219025568896E-05" />
    </inertial>
    <visual>
      <origin
        xyz="0 0 0"
        rpy="0 0 0" />
      <geometry>
        <mesh
          filename="package://gemini_description/meshes/l_shoulder_ball.STL" />
      </geometry>
      <material
        name="">
        <color
          rgba="1 1 1 1" />
      </material>
    </visual>
    <collision>
      <origin
        xyz="0 0 0"
        rpy="0 0 0" />
      <geometry>
        <mesh
          filename="package://gemini_description/meshes/l_shoulder_ball.STL" />
      </geometry>
    </collision>
  </link>
  <joint
    name="ls1"
    type="continuous">
    <origin
      xyz="0.5342 -1.2006 1.1783"
      rpy="1.5708 -0.0040924 3.1416" />
    <parent
      link="base_link" />
    <child
      link="l_shoulder_ball" />
    <axis
      xyz="0 0 1" />
  </joint>
  <link
    name="l_bicpet">
    <inertial>
      <origin
        xyz="-0.00100559107551246 2.46885547117159E-06 0.103420375905642"
        rpy="0 0 0" />
      <mass
        value="0.272459883078294" />
      <inertia
        ixx="0.000714949499290933"
        ixy="-1.17195329165913E-05"
        ixz="-2.94068577364188E-09"
        iyy="0.00057388488980549"
        iyz="-2.95939815462351E-08"
        izz="0.000255692740695557" />
    </inertial>
    <visual>
      <origin
        xyz="0 0 0"
        rpy="0 0 0" />
      <geometry>
        <mesh
          filename="package://gemini_description/meshes/l_bicpet.STL" />
      </geometry>
      <material
        name="">
        <color
          rgba="1 1 1 1" />
      </material>
    </visual>
    <collision>
      <origin
        xyz="0 0 0"
        rpy="0 0 0" />
      <geometry>
        <mesh
          filename="package://gemini_description/meshes/l_bicpet.STL" />
      </geometry>
    </collision>
  </link>
  <joint
    name="ls2"
    type="continuous">
    <origin
      xyz="0 0 -0.05"
      rpy="0 -1.5481 1.5708" />
    <parent
      link="l_shoulder_ball" />
    <child
      link="l_bicpet" />
    <axis
      xyz="0 1 0" />
  </joint>
  <link
    name="l_elbow_ball">
    <inertial>
      <origin
        xyz="5.579627426755E-09 3.33881799985392E-09 -0.0411716393287667"
        rpy="0 0 0" />
      <mass
        value="0.0544711805998191" />
      <inertia
        ixx="4.16386350282785E-05"
        ixy="-8.01710968800043E-11"
        ixz="-7.0816695151809E-12"
        iyy="4.6285115671902E-05"
        iyz="-3.51591159105833E-11"
        izz="3.82219030866655E-05" />
    </inertial>
    <visual>
      <origin
        xyz="0 0 0"
        rpy="0 0 0" />
      <geometry>
        <mesh
          filename="package://gemini_description/meshes/l_elbow_ball.STL" />
      </geometry>
      <material
        name="">
        <color
          rgba="1 1 1 1" />
      </material>
    </visual>
    <collision>
      <origin
        xyz="0 0 0"
        rpy="0 0 0" />
      <geometry>
        <mesh
          filename="package://gemini_description/meshes/l_elbow_ball.STL" />
      </geometry>
    </collision>
  </link>
  <joint
    name="le1"
    type="continuous">
    <origin
      xyz="-0.0010053 0 0.24065"
      rpy="-3.1416 0 0.00012242" />
    <parent
      link="l_bicpet" />
    <child
      link="l_elbow_ball" />
    <axis
      xyz="0 0 1" />
  </joint>
  <link
    name="l_forearm">
    <inertial>
      <origin
        xyz="-0.0134818917302594 -0.135163444602353 -0.00225492505633373"
        rpy="0 0 0" />
      <mass
        value="0.399020633136461" />
      <inertia
        ixx="0.000800265445630859"
        ixy="-5.11977241866111E-05"
        ixz="8.94994643330891E-06"
        iyy="0.000304300255531217"
        iyz="-1.29246447280753E-05"
        izz="0.000582445526550097" />
    </inertial>
    <visual>
      <origin
        xyz="0 0 0"
        rpy="0 0 0" />
      <geometry>
        <mesh
          filename="package://gemini_description/meshes/l_forearm.STL" />
      </geometry>
      <material
        name="">
        <color
          rgba="0.792156862745098 0.819607843137255 0.933333333333333 1" />
      </material>
    </visual>
    <collision>
      <origin
        xyz="0 0 0"
        rpy="0 0 0" />
      <geometry>
        <mesh
          filename="package://gemini_description/meshes/l_forearm.STL" />
      </geometry>
    </collision>
  </link>
  <joint
    name="le2"
    type="continuous">
    <origin
      xyz="0 0 -0.05"
      rpy="1.5481 -0.0040913 -1.5706" />
    <parent
      link="l_elbow_ball" />
    <child
      link="l_forearm" />
    <axis
      xyz="0.00021537 0.022713 -0.99974" />
  </joint>
  <link
    name="l_wrist">
    <inertial>
      <origin
        xyz="0.0146201857300534 -5.55111512312578E-17 6.66133814775094E-16"
        rpy="0 0 0" />
      <mass
        value="0.0120708298165579" />
      <inertia
        ixx="4.50218447918877E-06"
        ixy="6.41892155341149E-22"
        ixz="8.87068488901867E-21"
        iyy="4.73440053913698E-06"
        iyz="1.94552880072472E-20"
        izz="1.51423045487238E-06" />
    </inertial>
    <visual>
      <origin
        xyz="0 0 0"
        rpy="0 0 0" />
      <geometry>
        <mesh
          filename="package://gemini_description/meshes/l_wrist.STL" />
      </geometry>
      <material
        name="">
        <color
          rgba="1 1 1 1" />
      </material>
    </visual>
    <collision>
      <origin
        xyz="0 0 0"
        rpy="0 0 0" />
      <geometry>
        <mesh
          filename="package://gemini_description/meshes/l_wrist.STL" />
      </geometry>
    </collision>
  </link>
  <joint
    name="lw1"
    type="continuous">
    <origin
      xyz="-0.023534 -0.23755 -0.0053292"
      rpy="-0.2299 0.022623 -1.6708" />
    <parent
      link="l_forearm" />
    <child
      link="l_wrist" />
    <axis
      xyz="1 0 0" />
  </joint>
  <link
    name="l_hand">
    <inertial>
      <origin
        xyz="0.0619078942618763 0.00451726047115408 0.000800417664037212"
        rpy="0 0 0" />
      <mass
        value="0.178970864334337" />
      <inertia
        ixx="0.00013652753958862"
        ixy="2.96471792691893E-05"
        ixz="2.8119687235718E-06"
        iyy="0.000265184422458029"
        iyz="5.35801832253925E-07"
        izz="0.000391228773611264" />
    </inertial>
    <visual>
      <origin
        xyz="0 0 0"
        rpy="0 0 0" />
      <geometry>
        <mesh
          filename="package://gemini_description/meshes/l_hand.STL" />
      </geometry>
      <material
        name="">
        <color
          rgba="0.792156862745098 0.819607843137255 0.933333333333333 1" />
      </material>
    </visual>
    <collision>
      <origin
        xyz="0 0 0"
        rpy="0 0 0" />
      <geometry>
        <mesh
          filename="package://gemini_description/meshes/l_hand.STL" />
      </geometry>
    </collision>
  </link>
  <joint
    name="lw2"
    type="continuous">
    <origin
      xyz="0.030114 0 0"
      rpy="-1.5708 0 0.091473" />
    <parent
      link="l_wrist" />
    <child
      link="l_hand" />
    <axis
      xyz="0 1 0" />
  </joint>
<transmission name="trans_rs1">
        <type>transmission_interface/SimpleTransmission</type>
        <joint name="rs1">
            <hardwareInterface>hardware_interface/EffortJointInterface</hardwareInterface>
        </joint>
        <actuator name="rs1_motor">
            <hardwareInterface>hardware_interface/EffortJointInterface</hardwareInterface>
            <mechanicalReduction>1</mechanicalReduction>
        </actuator>
    </transmission>
    <transmission name="trans_rs2">
        <type>transmission_interface/SimpleTransmission</type>
        <joint name="rs2">
            <hardwareInterface>hardware_interface/EffortJointInterface</hardwareInterface>
        </joint>
        <actuator name="rs2_motor">
            <hardwareInterface>hardware_interface/EffortJointInterface</hardwareInterface>
            <mechanicalReduction>1</mechanicalReduction>
        </actuator>
    </transmission>
    <transmission name="trans_re1">
        <type>transmission_interface/SimpleTransmission</type>
        <joint name="re1">
            <hardwareInterface>hardware_interface/EffortJointInterface</hardwareInterface>
        </joint>
        <actuator name="re1_motor">
            <hardwareInterface>hardware_interface/EffortJointInterface</hardwareInterface>
            <mechanicalReduction>1</mechanicalReduction>
        </actuator>
    </transmission>
    <transmission name="trans_re2">
        <type>transmission_interface/SimpleTransmission</type>
        <joint name="re2">
            <hardwareInterface>hardware_interface/EffortJointInterface</hardwareInterface>
        </joint>
        <actuator name="re2_motor">
            <hardwareInterface>hardware_interface/EffortJointInterface</hardwareInterface>
            <mechanicalReduction>1</mechanicalReduction>
        </actuator>
    </transmission>
    <transmission name="trans_rw1">
        <type>transmission_interface/SimpleTransmission</type>
        <joint name="rw1">
            <hardwareInterface>hardware_interface/EffortJointInterface</hardwareInterface>
        </joint>
        <actuator name="rw1_motor">
            <hardwareInterface>hardware_interface/EffortJointInterface</hardwareInterface>
            <mechanicalReduction>1</mechanicalReduction>
        </actuator>
    </transmission>
    <transmission name="trans_rw2">
        <type>transmission_interface/SimpleTransmission</type>
        <joint name="rw2">
            <hardwareInterface>hardware_interface/EffortJointInterface</hardwareInterface>
        </joint>
        <actuator name="rw2_motor">
            <hardwareInterface>hardware_interface/EffortJointInterface</hardwareInterface>
            <mechanicalReduction>1</mechanicalReduction>
        </actuator>
    </transmission>
    <transmission name="trans_ls1">
        <type>transmission_interface/SimpleTransmission</type>
        <joint name="ls1">
            <hardwareInterface>hardware_interface/EffortJointInterface</hardwareInterface>
        </joint>
        <actuator name="ls1_motor">
            <hardwareInterface>hardware_interface/EffortJointInterface</hardwareInterface>
            <mechanicalReduction>1</mechanicalReduction>
        </actuator>
    </transmission>
    <transmission name="trans_ls2">
        <type>transmission_interface/SimpleTransmission</type>
        <joint name="ls2">
            <hardwareInterface>hardware_interface/EffortJointInterface</hardwareInterface>
        </joint>
        <actuator name="ls2_motor">
            <hardwareInterface>hardware_interface/EffortJointInterface</hardwareInterface>
            <mechanicalReduction>1</mechanicalReduction>
        </actuator>
    </transmission>
    <transmission name="trans_le1">
        <type>transmission_interface/SimpleTransmission</type>
        <joint name="le1">
            <hardwareInterface>hardware_interface/EffortJointInterface</hardwareInterface>
        </joint>
        <actuator name="le1_motor">
            <hardwareInterface>hardware_interface/EffortJointInterface</hardwareInterface>
            <mechanicalReduction>1</mechanicalReduction>
        </actuator>
    </transmission>
    <transmission name="trans_le2">
        <type>transmission_interface/SimpleTransmission</type>
        <joint name="le2">
            <hardwareInterface>hardware_interface/EffortJointInterface</hardwareInterface>
        </joint>
        <actuator name="le2_motor">
            <hardwareInterface>hardware_interface/EffortJointInterface</hardwareInterface>
            <mechanicalReduction>1</mechanicalReduction>
        </actuator>
    </transmission>
    <transmission name="trans_lw1">
        <type>transmission_interface/SimpleTransmission</type>
        <joint name="lw1">
            <hardwareInterface>hardware_interface/EffortJointInterface</hardwareInterface>
        </joint>
        <actuator name="lw1_motor">
            <hardwareInterface>hardware_interface/EffortJointInterface</hardwareInterface>
            <mechanicalReduction>1</mechanicalReduction>
        </actuator>
    </transmission>
    <transmission name="trans_lw2">
        <type>transmission_interface/SimpleTransmission</type>
        <joint name="lw2">
            <hardwareInterface>hardware_interface/EffortJointInterface</hardwareInterface>
        </joint>
        <actuator name="lw2_motor">
            <hardwareInterface>hardware_interface/EffortJointInterface</hardwareInterface>
            <mechanicalReduction>1</mechanicalReduction>
        </actuator>
    </transmission>
    <gazebo>
        <plugin name="gazebo_ros_control" filename="libgazebo_ros_control.so">
            <robotNamespace>/</robotNamespace>
        </plugin>
    </gazebo>
    <transmission name="trans_rs1">
        <type>transmission_interface/SimpleTransmission</type>
        <joint name="rs1">
            <hardwareInterface>hardware_interface/EffortJointInterface</hardwareInterface>
        </joint>
        <actuator name="rs1_motor">
            <hardwareInterface>hardware_interface/EffortJointInterface</hardwareInterface>
            <mechanicalReduction>1</mechanicalReduction>
        </actuator>
    </transmission>
    <transmission name="trans_rs2">
        <type>transmission_interface/SimpleTransmission</type>
        <joint name="rs2">
            <hardwareInterface>hardware_interface/EffortJointInterface</hardwareInterface>
        </joint>
        <actuator name="rs2_motor">
            <hardwareInterface>hardware_interface/EffortJointInterface</hardwareInterface>
            <mechanicalReduction>1</mechanicalReduction>
        </actuator>
    </transmission>
    <transmission name="trans_re1">
        <type>transmission_interface/SimpleTransmission</type>
        <joint name="re1">
            <hardwareInterface>hardware_interface/EffortJointInterface</hardwareInterface>
        </joint>
        <actuator name="re1_motor">
            <hardwareInterface>hardware_interface/EffortJointInterface</hardwareInterface>
            <mechanicalReduction>1</mechanicalReduction>
        </actuator>
    </transmission>
    <transmission name="trans_re2">
        <type>transmission_interface/SimpleTransmission</type>
        <joint name="re2">
            <hardwareInterface>hardware_interface/EffortJointInterface</hardwareInterface>
        </joint>
        <actuator name="re2_motor">
            <hardwareInterface>hardware_interface/EffortJointInterface</hardwareInterface>
            <mechanicalReduction>1</mechanicalReduction>
        </actuator>
    </transmission>
    <transmission name="trans_rw1">
        <type>transmission_interface/SimpleTransmission</type>
        <joint name="rw1">
            <hardwareInterface>hardware_interface/EffortJointInterface</hardwareInterface>
        </joint>
        <actuator name="rw1_motor">
            <hardwareInterface>hardware_interface/EffortJointInterface</hardwareInterface>
            <mechanicalReduction>1</mechanicalReduction>
        </actuator>
    </transmission>
    <transmission name="trans_rw2">
        <type>transmission_interface/SimpleTransmission</type>
        <joint name="rw2">
            <hardwareInterface>hardware_interface/EffortJointInterface</hardwareInterface>
        </joint>
        <actuator name="rw2_motor">
            <hardwareInterface>hardware_interface/EffortJointInterface</hardwareInterface>
            <mechanicalReduction>1</mechanicalReduction>
        </actuator>
    </transmission>
    <transmission name="trans_ls1">
        <type>transmission_interface/SimpleTransmission</type>
        <joint name="ls1">
            <hardwareInterface>hardware_interface/EffortJointInterface</hardwareInterface>
        </joint>
        <actuator name="ls1_motor">
            <hardwareInterface>hardware_interface/EffortJointInterface</hardwareInterface>
            <mechanicalReduction>1</mechanicalReduction>
        </actuator>
    </transmission>
    <transmission name="trans_ls2">
        <type>transmission_interface/SimpleTransmission</type>
        <joint name="ls2">
            <hardwareInterface>hardware_interface/EffortJointInterface</hardwareInterface>
        </joint>
        <actuator name="ls2_motor">
            <hardwareInterface>hardware_interface/EffortJointInterface</hardwareInterface>
            <mechanicalReduction>1</mechanicalReduction>
        </actuator>
    </transmission>
    <transmission name="trans_le1">
        <type>transmission_interface/SimpleTransmission</type>
        <joint name="le1">
            <hardwareInterface>hardware_interface/EffortJointInterface</hardwareInterface>
        </joint>
        <actuator name="le1_motor">
            <hardwareInterface>hardware_interface/EffortJointInterface</hardwareInterface>
            <mechanicalReduction>1</mechanicalReduction>
        </actuator>
    </transmission>
    <transmission name="trans_le2">
        <type>transmission_interface/SimpleTransmission</type>
        <joint name="le2">
            <hardwareInterface>hardware_interface/EffortJointInterface</hardwareInterface>
        </joint>
        <actuator name="le2_motor">
            <hardwareInterface>hardware_interface/EffortJointInterface</hardwareInterface>
            <mechanicalReduction>1</mechanicalReduction>
        </actuator>
    </transmission>
    <transmission name="trans_lw1">
        <type>transmission_interface/SimpleTransmission</type>
        <joint name="lw1">
            <hardwareInterface>hardware_interface/EffortJointInterface</hardwareInterface>
        </joint>
        <actuator name="lw1_motor">
            <hardwareInterface>hardware_interface/EffortJointInterface</hardwareInterface>
            <mechanicalReduction>1</mechanicalReduction>
        </actuator>
    </transmission>
    <transmission name="trans_lw2">
        <type>transmission_interface/SimpleTransmission</type>
        <joint name="lw2">
            <hardwareInterface>hardware_interface/EffortJointInterface</hardwareInterface>
        </joint>
        <actuator name="lw2_motor">
            <hardwareInterface>hardware_interface/EffortJointInterface</hardwareInterface>
            <mechanicalReduction>1</mechanicalReduction>
        </actuator>
    </transmission>
    <gazebo>
        <plugin name="gazebo_ros_control" filename="libgazebo_ros_control.so">
            <robotNamespace>/</robotNamespace>
        </plugin>
    </gazebo>
</robot>
